I'm sorry, but an uncaught exception occurred.

While running game code:
  File "game/scripts/profile.rpy", line 36, in script call
    call tips.give
  File "game/scripts/tips.rpy", line 105, in script call
    call tips.pick
  File "game/scripts/tips.rpy", line 114, in script
    python:
  File "game/scripts/tips.rpy", line 134, in <module>
    part_1 = tip["part 1"]
KeyError: 'part 1'

-- Full Traceback ------------------------------------------------------------

Full traceback:
  File "game/scripts/profile.rpy", line 36, in script call
    call tips.give
  File "game/scripts/tips.rpy", line 105, in script call
    call tips.pick
  File "game/scripts/tips.rpy", line 114, in script
    python:
  File "/Users/aljo/Downloads/5y1s/psych 180/renpy-8.2.0-sdk/renpy/ast.py", line 823, in execute
    renpy.python.py_exec_bytecode(self.code.bytecode, self.hide, store=self.store)
  File "/Users/aljo/Downloads/5y1s/psych 180/renpy-8.2.0-sdk/renpy/python.py", line 1178, in py_exec_bytecode
    exec(bytecode, globals, locals)
  File "game/scripts/tips.rpy", line 134, in <module>
    part_1 = tip["part 1"]
KeyError: 'part 1'

macOS-15.0.1-arm64-arm-64bit arm64
Ren'Py 8.2.0.24012702
Simmer 1.0
Sat Nov  2 15:19:37 2024
